<robot name="Fliessband">
    <link name="link_2">
        <inertial>
            <origin xyz="-97 1.5 -0.15" rpy="0.0 0.0 0.0"/>
            <mass value="500000"/>
            <inertia ixx="52083.3" ixy="0.0" ixz="0.0" iyy="4.16677e+08" iyz="0.0" izz="4.16708e+08"/>
        </inertial>
        <visual name="">
            <origin xyz="-97 1.5 -0.15" rpy="0.0 0.0 0.0"/>
            <geometry>
                <box size="200 1 0.5"/>
            </geometry>
            <material name="">
                <color rgba="0.0 0.0 1.0 1.0"/>
                <texture filename=""/>
            </material>
        </visual>
        <collision>
            <origin xyz="-97 1.5 -0.15" rpy="0.0 0.0 0.0"/>
            <geometry>
                <box size="200 1 0.5"/>
            </geometry>
        </collision>
 
    </link>


    <link name="link_2_clone">
        <inertial>
            <origin xyz="-97 1.5 0.15" rpy="0.0 0.0 0.0"/>
            <mass value="20000"/>
            <inertia ixx="1041.67" ixy="0.0" ixz="0.0" iyy="8.33354e+06" iyz="0.0" izz="8.33354e+06"/>
        </inertial>
        <visual name="">
            <origin xyz="-97 1.5 0.15" rpy="0.0 0.0 0.0"/>
            <geometry>
                <box size="200 0.8 0.01"/>
            </geometry>
            <material name="">
                <color rgba="1.0 0.0 0.0 0.0"/>
                <texture filename=""/>
            </material>
        </visual>
        <collision>
            <origin xyz="-97 1.5 0.15" rpy="0.0 0.0 0.0"/>
            <geometry>
                <box size="200 0.8 0.01"/>
            </geometry>
        </collision>
    </link>


    <link name="link_2_clone_clone">
        <inertial>
            <origin xyz="-97 1.5 0.17" rpy="0.0 0.0 0.0"/>
            <mass value="200"/>
            <inertia ixx="10" ixy="0.0" ixz="0.0" iyy="20000" iyz="0.0" izz="20000"/>
        </inertial>
        <visual name="">
            <origin xyz="-97 1.5 0.17" rpy="0.0 0.0 0.0"/>
            <geometry>
                <box size="200 0.8 0.01"/>
            </geometry>
            <material name="">
                <color rgba="0.0 1.0 0.0 0.0"/>
                <texture filename=""/>
            </material>
        </visual>
        <collision>
            <origin xyz="-97 1.5 0.17" rpy="0.0 0.0 0.0"/>
            <geometry>
                <box size="200 0.8 0.01"/>
            </geometry>
        </collision>
    </link>

    <gazebo reference="link_2_clone_clone">
      <kp>2000000.0</kp>
      <kd>2000.0</kd>
      <mu1>200000.0</mu1>
      <mu2>200000.0</mu2>
      <minDepth>0.000000000000001</minDepth>
    </gazebo>

    <joint name="notMovable" type="prismatic">
        <parent link="link_2"/>
        <child link="link_2_clone"/>
        <limit effort="-1.0" lower="0" upper="0" velocity="-1.0"/>
        <origin rpy="0 0 0" xyz="0 0 0"/>
      </joint>

    <joint name="Movable" type="prismatic">
        <parent link="link_2"/>
        <child link="link_2_clone_clone"/>
        <limit effort="200.0" lower="-200000" upper="200000" velocity="0.5"/>
        <origin rpy="0 0 0" xyz="0 0 0"/>
      </joint>

      <gazebo reference="link_2">
       <material>Gazebo/White</material>
      </gazebo>

      <gazebo reference="link_2_clone">
       <material>Gazebo/Black</material>
      </gazebo>

      <gazebo reference="link_2_clone_clone">
       <material>Gazebo/Black</material>
      </gazebo>

</robot>