<robot name="objects">
      <link name="redBox1">
        <inertial>
          <origin xyz="0.11 1.435 0.61" />
          <mass value="0.985" />
          <inertia  ixx="0.0004104" ixy="0.0"  ixz="0.0"  iyy="0.0004104"  iyz="0.0"  izz="0.0004104" />
        </inertial>
        <visual>
          <origin xyz="0.11 1.435 0.61"/>
         <geometry>
           <box size="0.05 0.05 0.05" />
         </geometry>
       </visual>
       <collision>
         <origin xyz="0.11 1.435 0.61"/>
         <geometry>
           <box size="0.05 0.05 0.05" />
         </geometry>
       </collision>
     </link>

     <gazebo reference="redBox1">
       <material>Gazebo/Red</material>
       <kp>100000000.0</kp>
        <kd>1000.0</kd>
        <mu1>100000.0</mu1>
        <mu2>100000.0</mu2>
        <minDepth>0.000001</minDepth>
      </gazebo>

      <link name="redBox0">
        <inertial>
          <origin xyz="-3.00 1.5 0.61" />
          <mass value="0.985" />
          <inertia  ixx="0.0004104" ixy="0.0"  ixz="0.0"  iyy="0.0004104"  iyz="0.0"  izz="0.0004104" />
        </inertial>
        <visual>
          <origin xyz="-3.00 1.5 0.61"/>
         <geometry>
           <box size="0.05 0.05 0.05" />
         </geometry>
       </visual>
       <collision>
         <origin xyz="-3.00 1.5 0.61"/>
         <geometry>
           <box size="0.05 0.05 0.05" />
         </geometry>
       </collision>
     </link>

     <gazebo reference="redBox0">
       <material>Gazebo/Red</material>
      </gazebo>


      <link name="blueBox1">
        <inertial>
          <origin xyz="-6 1.435 0.61" />
          <mass value="0.985" />
          <inertia  ixx="0.0004104" ixy="0.0"  ixz="0.0"  iyy="0.0004104"  iyz="0.0"  izz="0.0004104" />
        </inertial>
        <visual>
          <origin xyz="-6 1.435 0.61"/>
         <geometry>
           <box size="0.05 0.05 0.05" />
         </geometry>
         <material name="">
                <color rgba="0.0 0.0 1.0 1.0"/>
                <texture filename=""/>
            </material>
       </visual>
       <collision>
         <origin xyz="-6 1.435 0.61"/>
         <geometry>
           <box size="0.05 0.05 0.05" />
         </geometry>
       </collision>
     </link>
     <gazebo reference="blueBox1">
       <material>Gazebo/Blue</material>
      </gazebo>

      <joint name="joint0" type="floating">
        <origin xyz="0 0 0" rpy="0 0 0"/>
        <parent link="redBox1"/>
       <child link="redBox0"/>
    
        <calibration rising="0.0"/>
        <dynamics damping="0.0" friction="0.0"/>
        <limit effort="30" velocity="1.0" lower="-2.2" upper="0.7" />
        <safety_controller k_velocity="10" k_position="15" soft_lower_limit="-2.0" soft_upper_limit="0.5" />
    </joint>

      <joint name="joint1" type="floating">
        <origin xyz="0 0 0" rpy="0 0 0"/>
        <parent link="redBox1"/>
       <child link="blueBox1"/>
    
        <calibration rising="0.0"/>
        <dynamics damping="0.0" friction="0.0"/>
        <limit effort="30" velocity="1.0" lower="-2.2" upper="0.7" />
        <safety_controller k_velocity="10" k_position="15" soft_lower_limit="-2.0" soft_upper_limit="0.5" />
    </joint>

      <link name="greenCylinder1">
        <inertial>
          <origin xyz="-9 1.435 0.61" />
          <mass value="0.773" />
          <inertia  ixx="0.0002818" ixy="0.0"  ixz="0.0"  iyy="0.0002818"  iyz="0.0"  izz="0.0002416" />
        </inertial>
        <visual>
          <origin xyz="-9 1.435 0.61"/>
         <geometry>
           <cylinder length="0.05" radius="0.025"/>
         </geometry>
         <material name="">
                <color rgba="0.0 1.0 0.0 1.0"/>
                <texture filename=""/>
            </material>
       </visual>
       <collision>
         <origin xyz="-9 1.435 0.61"/>
         <geometry>
           <cylinder length="0.05" radius="0.025"/>
         </geometry>
       </collision>
     </link>
     <gazebo reference="greenCylinder1">
       <material>Gazebo/Green</material>
      </gazebo>

       <joint name="joint2" type="floating">
        <origin xyz="0 0 0" rpy="0 0 0"/>
        <parent link="redBox1"/>
       <child link="greenCylinder1"/>
    
        <calibration rising="0.0"/>
        <dynamics damping="0.0" friction="0.0"/>
        <limit effort="30" velocity="1.0" lower="-2.2" upper="0.7" />
        <safety_controller k_velocity="10" k_position="15" soft_lower_limit="-2.0" soft_upper_limit="0.5" />
    </joint>

      <link name="greenBox1">
        <inertial>
          <origin xyz="-12 1.435 0.61" />
          <mass value="0.985" />
          <inertia  ixx="0.0004104" ixy="0.0"  ixz="0.0"  iyy="0.0004104"  iyz="0.0"  izz="0.0004104" />
        </inertial>
        <visual>
          <origin xyz="-12 1.435 0.61"/>
         <geometry>
           <box size="0.05 0.05 0.05" />
         </geometry>
         <material name="">
                <color rgba="0.0 1.0 0.0 1.0"/>
                <texture filename=""/>
            </material>
       </visual>
       <collision>
         <origin xyz="-12 1.435 0.61"/>
         <geometry>
           <box size="0.05 0.05 0.05" />
         </geometry>
       </collision>
     </link>
     <gazebo reference="greenBox1">
       <material>Gazebo/Green</material>
      </gazebo>

      <joint name="joint3" type="floating">
        <origin xyz="0 0 0" rpy="0 0 0"/>
        <parent link="redBox1"/>
       <child link="greenBox1"/>
    
        <calibration rising="0.0"/>
        <dynamics damping="0.0" friction="0.0"/>
        <limit effort="30" velocity="1.0" lower="-2.2" upper="0.7" />
        <safety_controller k_velocity="10" k_position="15" soft_lower_limit="-2.0" soft_upper_limit="0.5" />
    </joint>

    <link name="redCylinder1">
        <inertial>
          <origin xyz="-15 1.435 0.61" />
          <mass value="0.773" />
          <inertia  ixx="0.0002818" ixy="0.0"  ixz="0.0"  iyy="0.0002818"  iyz="0.0"  izz="0.0002416" />
        </inertial>
        <visual>
          <origin xyz="-15 1.435 0.61"/>
         <geometry>
           <cylinder length="0.05" radius="0.025"/>
         </geometry>
         <material name="">
                <color rgba="1.0 0.0 0.0 1.0"/>
                <texture filename=""/>
            </material>
       </visual>
       <collision>
         <origin xyz="-15 1.435 0.61"/>
         <geometry>
           <cylinder length="0.05" radius="0.025"/>
         </geometry>
       </collision>
     </link>
     <gazebo reference="redCylinder1">
       <material>Gazebo/Red</material>
      </gazebo>

       <joint name="joint4" type="floating">
        <origin xyz="0 0 0" rpy="0 0 0"/>
        <parent link="redBox1"/>
       <child link="redCylinder1"/>
    
        <calibration rising="0.0"/>
        <dynamics damping="0.0" friction="0.0"/>
        <limit effort="30" velocity="1.0" lower="-2.2" upper="0.7" />
        <safety_controller k_velocity="10" k_position="15" soft_lower_limit="-2.0" soft_upper_limit="0.5" />
    </joint>


      <link name="blueBox2">
        <inertial>
          <origin xyz="-18 1.435 0.61" />
          <mass value="0.985" />
          <inertia  ixx="0.0004104" ixy="0.0"  ixz="0.0"  iyy="0.0004104"  iyz="0.0"  izz="0.0004104" />
        </inertial>
        <visual>
          <origin xyz="-18 1.435 0.61"/>
         <geometry>
           <box size="0.05 0.05 0.05" />
         </geometry>
         <material name="">
                <color rgba="0.0 0.0 1.0 1.0"/>
                <texture filename=""/>
            </material>
       </visual>
       <collision>
         <origin xyz="-18 1.435 0.61"/>
         <geometry>
           <box size="0.05 0.05 0.05" />
         </geometry>
       </collision>
     </link>
     <gazebo reference="blueBox2">
       <material>Gazebo/Blue</material>
      </gazebo>

      <joint name="joint5" type="floating">
        <origin xyz="0 0 0" rpy="0 0 0"/>
        <parent link="redBox1"/>
       <child link="blueBox2"/>
    
        <calibration rising="0.0"/>
        <dynamics damping="0.0" friction="0.0"/>
        <limit effort="30" velocity="1.0" lower="-2.2" upper="0.7" />
        <safety_controller k_velocity="10" k_position="15" soft_lower_limit="-2.0" soft_upper_limit="0.5" />
    </joint>

    <link name="blueCylinder1">
        <inertial>
          <origin xyz="-21 1.435 0.61" />
          <mass value="0.773" />
          <inertia  ixx="0.0002818" ixy="0.0"  ixz="0.0"  iyy="0.0002818"  iyz="0.0"  izz="0.0002416" />
        </inertial>
        <visual>
          <origin xyz="-21 1.435 0.61"/>
         <geometry>
           <cylinder length="0.05" radius="0.025"/>
         </geometry>
         <material name="">
                <color rgba="0.0 0.0 1.0 1.0"/>
                <texture filename=""/>
            </material>
       </visual>
       <collision>
         <origin xyz="-21 1.435 0.61"/>
         <geometry>
           <cylinder length="0.05" radius="0.025"/>
         </geometry>
       </collision>
     </link>
     <gazebo reference="blueCylinder1">
       <material>Gazebo/Blue</material>
      </gazebo>

       <joint name="joint6" type="floating">
        <origin xyz="0 0 0" rpy="0 0 0"/>
        <parent link="redBox1"/>
       <child link="blueCylinder1"/>
    
        <calibration rising="0.0"/>
        <dynamics damping="0.0" friction="0.0"/>
        <limit effort="30" velocity="1.0" lower="-2.2" upper="0.7" />
        <safety_controller k_velocity="10" k_position="15" soft_lower_limit="-2.0" soft_upper_limit="0.5" />
    </joint>

      <link name="redBox2">
        <inertial>
          <origin xyz="-24 1.435 0.61" />
          <mass value="0.985" />
          <inertia  ixx="0.0004104" ixy="0.0"  ixz="0.0"  iyy="0.0004104"  iyz="0.0"  izz="0.0004104" />
        </inertial>
        <visual>
          <origin xyz="-24 1.435 0.61"/>
         <geometry>
           <box size="0.05 0.05 0.05" />
         </geometry>
       </visual>
       <collision>
         <origin xyz="-24 1.435 0.61"/>
         <geometry>
           <box size="0.05 0.05 0.05" />
         </geometry>
       </collision>
     </link>
     <gazebo reference="redBox2">
       <material>Gazebo/Red</material>
      </gazebo>

      <joint name="joint7" type="floating">
        <origin xyz="0 0 0" rpy="0 0 0"/>
        <parent link="redBox1"/>
       <child link="redBox2"/>
    
        <calibration rising="0.0"/>
        <dynamics damping="0.0" friction="0.0"/>
        <limit effort="30" velocity="1.0" lower="-2.2" upper="0.7" />
        <safety_controller k_velocity="10" k_position="15" soft_lower_limit="-2.0" soft_upper_limit="0.5" />
    </joint>

    <link name="redCylinder2">
        <inertial>
          <origin xyz="-27 1.435 0.61" />
          <mass value="0.773" />
          <inertia  ixx="0.0002818" ixy="0.0"  ixz="0.0"  iyy="0.0002818"  iyz="0.0"  izz="0.0002416" />
        </inertial>
        <visual>
          <origin xyz="-27 1.435 0.61"/>
         <geometry>
           <cylinder length="0.05" radius="0.025"/>
         </geometry>
         <material name="">
                <color rgba="1.0 0.0 0.0 1.0"/>
                <texture filename=""/>
            </material>
       </visual>
       <collision>
         <origin xyz="-27 1.435 0.61"/>
         <geometry>
           <cylinder length="0.05" radius="0.025"/>
         </geometry>
       </collision>
     </link>
     <gazebo reference="redCylinder2">
       <material>Gazebo/Red</material>
      </gazebo>

       <joint name="joint8" type="floating">
        <origin xyz="0 0 0" rpy="0 0 0"/>
        <parent link="redBox1"/>
       <child link="redCylinder2"/>
    
        <calibration rising="0.0"/>
        <dynamics damping="0.0" friction="0.0"/>
        <limit effort="30" velocity="1.0" lower="-2.2" upper="0.7" />
        <safety_controller k_velocity="10" k_position="15" soft_lower_limit="-2.0" soft_upper_limit="0.5" />
    </joint>


      <link name="greenBox2">
        <inertial>
          <origin xyz="-30 1.435 0.61" />
          <mass value="0.985" />
          <inertia  ixx="0.0004104" ixy="0.0"  ixz="0.0"  iyy="0.0004104"  iyz="0.0"  izz="0.0004104" />
        </inertial>
        <visual>
          <origin xyz="-30 1.435 0.61"/>
         <geometry>
           <box size="0.05 0.05 0.05" />
         </geometry>
         <material name="">
                <color rgba="0.0 1.0 0.0 1.0"/>
                <texture filename=""/>
            </material>
       </visual>
       <collision>
         <origin xyz="-30 1.435 0.61"/>
         <geometry>
           <box size="0.05 0.05 0.05" />
         </geometry>
       </collision>
     </link>
     <gazebo reference="greenBox2">
       <material>Gazebo/Green</material>
      </gazebo>

      <joint name="joint9" type="floating">
        <origin xyz="0 0 0" rpy="0 0 0"/>
        <parent link="redBox1"/>
       <child link="greenBox2"/>
    
        <calibration rising="0.0"/>
        <dynamics damping="0.0" friction="0.0"/>
        <limit effort="30" velocity="1.0" lower="-2.2" upper="0.7" />
        <safety_controller k_velocity="10" k_position="15" soft_lower_limit="-2.0" soft_upper_limit="0.5" />
    </joint>


    <link name="greenCylinder2">
        <inertial>
          <origin xyz="-33 1.435 0.61" />
          <mass value="0.773" />
          <inertia  ixx="0.0002818" ixy="0.0"  ixz="0.0"  iyy="0.0002818"  iyz="0.0"  izz="0.0002416" />
        </inertial>
        <visual>
          <origin xyz="-33 1.435 0.61"/>
         <geometry>
           <cylinder length="0.05" radius="0.025"/>
         </geometry>
         <material name="">
                <color rgba="0.0 1.0 0.0 1.0"/>
                <texture filename=""/>
            </material>
       </visual>
       <collision>
         <origin xyz="-33 1.435 0.61"/>
         <geometry>
           <cylinder length="0.05" radius="0.025"/>
         </geometry>
       </collision>
     </link>
     <gazebo reference="greenCylinder2">
       <material>Gazebo/Green</material>
      </gazebo>

       <joint name="joint10" type="floating">
        <origin xyz="0 0 0" rpy="0 0 0"/>
        <parent link="redBox1"/>
       <child link="greenCylinder2"/>
    
        <calibration rising="0.0"/>
        <dynamics damping="0.0" friction="0.0"/>
        <limit effort="30" velocity="1.0" lower="-2.2" upper="0.7" />
        <safety_controller k_velocity="10" k_position="15" soft_lower_limit="-2.0" soft_upper_limit="0.5" />
    </joint>


    <link name="blueCylinder2">
        <inertial>
          <origin xyz="-36 1.435 0.61" />
          <mass value="0.773" />
          <inertia  ixx="0.0002818" ixy="0.0"  ixz="0.0"  iyy="0.0002818"  iyz="0.0"  izz="0.0002416" />
        </inertial>
        <visual>
          <origin xyz="-36 1.435 0.61"/>
         <geometry>
           <cylinder length="0.05" radius="0.025"/>
         </geometry>
         <material name="">
                <color rgba="0.0 0.0 1.0 1.0"/>
                <texture filename=""/>
            </material>
       </visual>
       <collision>
         <origin xyz="-36 1.435 0.61"/>
         <geometry>
           <cylinder length="0.05" radius="0.025"/>
         </geometry>
       </collision>
     </link>
     <gazebo reference="blueCylinder2">
       <material>Gazebo/Blue</material>
      </gazebo>

       <joint name="joint11" type="floating">
        <origin xyz="0 0 0" rpy="0 0 0"/>
        <parent link="redBox1"/>
       <child link="blueCylinder2"/>
    
        <calibration rising="0.0"/>
        <dynamics damping="0.0" friction="0.0"/>
        <limit effort="30" velocity="1.0" lower="-2.2" upper="0.7" />
        <safety_controller k_velocity="10" k_position="15" soft_lower_limit="-2.0" soft_upper_limit="0.5" />
    </joint>


      
  </robot>